<?xml version="1.0"?>
<robot name="r4" xmlns:xacro="http://ros.org/wiki/xacro">

    <!-- The base values are fixed from the modelling. Do not change-->
    <xacro:property name="base_length" value="0.09" />
    <xacro:property name="base_width" value="0.09" />
    <xacro:property name="base_height" value="0.02" />

    <xacro:property name="no" value="4" />

    <!-- Wheel parameters-->
    <xacro:property name="wheel_radius" value="0.040" />
    <xacro:property name="wheel_length" value="0.01" />
    <xacro:property name="wheel_x" value="-0.03" />
    <xacro:property name="left_wheel_y" value="0.050" />
    <xacro:property name="right_wheel_y" value="-0.050" />

    <!-- Caster parameters-->
    <xacro:property name="caster_base_radius" value="0.005" />
    <xacro:property name="caster_base_length" value="0.01" />
    <xacro:property name="caster_wheel_radius" value="0.015" />
    <xacro:property name="caster_wheel_length" value="0.01" />
    <xacro:property name="caster_base_x" value="0.040" />
    <xacro:property name="caster_base_z" value="-0.01" />
    <xacro:property name="caster_wheel_z" value="-0.02" />

    <!-- Main vehicle body-->
    <link name="vehicle_body_${no}">
        <inertial>
            <mass value="0.5" />
            <origin xyz="0 0 0" />
            <inertia ixx="0.001" ixy="0.0" ixz="0.0" iyy="0.001" iyz="0.0" izz="0.001" />
          </inertial>
        <collision>
            <geometry>
                <box size="${base_length} ${base_width} ${base_height}"/>
            </geometry>
            <surface>
                <friction>
                    <ode>
                        <mu>0.0</mu>
                        <mu2>0.0</mu2>
                    </ode>
                </friction>
                <contact>
                    <ode>
                        <kp>1000000.0</kp>
                        <kd>1000000.0</kd>
                    </ode>
                </contact>
            </surface>
        </collision>
        <visual>
            <geometry>
                <mesh filename="package://f1/meshes/m44.dae"/>
            </geometry>               
        </visual>
    </link>

    <!-- Dummy root link-->
    <link name="root_link"/>
    
    <!-- Joint for the root and base link-->
    <joint name="root_base_joint" type="fixed">
        <origin xyz="0.0 0.0 0.0" rpy="0.0 0.0 0.0"/>
        <parent link="root_link"/>
        <child link="vehicle_body_${no}"/>
        <axis xyz="0.0 0.0 0.0"/>
        <limit lower="0.0" upper="0.0" effort="0.0" velocity="0.0"/>
    </joint>

    <!-- Left wheel link-->
    <link name="left_wheel_${no}">
        <inertial>
            <origin xyz="0.0 0 0.0" rpy="1.57 0.0 0.0"/>
            <mass value="0.2"/>
            <inertia ixx="0.001" ixy="0.0" ixz="0.0" iyy="0.001" iyz="0.0" izz="0.001" />
        </inertial>
        <collision>
            <origin xyz="0.0 0 0.0" rpy="1.57 0.0 0.0"/>
            <geometry>
                <cylinder radius="${wheel_radius}" length="${wheel_length}"/>
            </geometry>
            
            <surface>
                <friction>
                    <ode>
                        <mu>0.3</mu>
                        <mu2>0.3</mu2>
                    </ode>
                </friction>
                <contact>
                    <ode>
                        <kp>1000000.0</kp>
                        <kd>1000000.0</kd>
                        <min_depth>0.0</min_depth>
                    </ode>
                </contact>
            </surface> 
        </collision>
        <visual>
            <origin xyz="0.0 0 0.0" rpy="1.57 0.0 0.0"/>
            <geometry>
                <cylinder radius="${wheel_radius}" length="${wheel_length}"/>
            </geometry>
        </visual>
    </link>

    <!-- Right wheel link-->
    <link name="right_wheel_${no}">
        <inertial>
            <origin xyz="0.0 0 0.0" rpy="1.57 0.0 0.0"/>
            <mass value="0.2"/>
            <inertia ixx="0.001" ixy="0.0" ixz="0.0" iyy="0.001" iyz="0.0" izz="0.001" />
        </inertial>
        <collision>
            <origin xyz="0.0 0 0.0" rpy="1.57 0.0 0.0"/>
            <geometry>
                <cylinder radius="${wheel_radius}" length="${wheel_length}"/>
            </geometry>

            <surface>
                <friction>
                    <ode>
                        <mu>0.3</mu>
                        <mu2>0.3</mu2>
                    </ode>
                </friction>
                <contact>
                    <ode>
                        <kp>1000000.0</kp>
                        <kd>1000000.0</kd>
                        <min_depth>0.0</min_depth>
                    </ode>
                </contact>
            </surface>
            
        </collision>
        <visual>
            <origin xyz="0.0 0 0.0" rpy="1.57 0.0 0.0"/>
            <geometry>
                <cylinder radius="${wheel_radius}" length="${wheel_length}"/>
            </geometry>
        </visual>
    </link>
    
    <!-- Left wheel to the base joint-->
    <joint name="left_wheel_joint_${no}" type="continuous">
        <origin xyz="${wheel_x} ${left_wheel_y} 0.0" rpy="0.0 0.0 0.0"/>
        <parent link="vehicle_body_${no}"/>
        <child link="left_wheel_${no}"/>
        <axis xyz="0.0 1.0 0.0"/>
    </joint>

    <!-- Right wheel to the base joint-->
    <joint name="right_wheel_joint_${no}" type="continuous">
        <origin xyz="${wheel_x} ${right_wheel_y} 0.0" rpy="0.0 0.0 0.0"/>
        <parent link="vehicle_body_${no}"/>
        <child link="right_wheel_${no}"/>
        <axis xyz="0.0 1.0 0.0"/>
    </joint>

    <!-- Left wheel transmission-->
    <transmission name="left_wheel_trans_${no}" type="SimpleTransmission">
        <type>transmission_interface/SimpleTransmission</type>
        <actuator name="left_wheel_motor_${no}">
            <mechanicalReduction>1</mechanicalReduction>
            <hardwareInterface>hardware_interface/VelocityJointInterface</hardwareInterface>
        </actuator>
        <joint name="left_wheel_joint_${no}">
            <hardwareInterface>hardware_interface/VelocityJointInterface</hardwareInterface>
        </joint>
    </transmission>

    <!-- Right wheel transmission-->
    <transmission name="right_wheel_trans_${no}" type="SimpleTransmission">
        <type>transmission_interface/SimpleTransmission</type>
        <actuator name="right_wheel_motor_${no}">
            <mechanicalReduction>1</mechanicalReduction>
            <hardwareInterface>hardware_interface/VelocityJointInterface</hardwareInterface>
        </actuator>
        <joint name="right_wheel_joint_${no}">
            <hardwareInterface>hardware_interface/VelocityJointInterface</hardwareInterface>
        </joint>
    </transmission>

    <!-- Caster wheel link-->
    <link name="caster_wheel_link_${no}">
        <inertial>
            <mass value="0.03837"/>
            <origin xyz="0.0 0.0 0.0"/>
            <inertia  ixx="0.000008221" ixy="0" ixz="0" iyy="0.000013003" iyz="0" izz="0.000008221" />
        </inertial>
        <visual>
            <origin xyz="0.0 0.0 0.0" rpy="1.57 0.0 0.0"/>
            <geometry>
                <cylinder radius="${caster_wheel_radius}" length="${caster_wheel_length}"/>
            </geometry>
        </visual>
        <collision>
            <origin xyz="0.0 0.0 0.0" rpy="1.57 0.0 0.0"/>
            <geometry>
                <cylinder radius="${caster_wheel_radius}" length="${caster_wheel_length}"/>
            </geometry>
        </collision>
    </link>

    <!-- Caster base link-->
    <link name="caster_base_link_${no}">
        <inertial>
            <mass value="0.06597" />
            <origin xyz="0.0 0.0 0.0"/>
            <inertia  ixx="0.000039912" ixy="0" ixz="0.000017794" iyy="0.000050728" iyz="0" izz="0.000035261" />
        </inertial>
        <visual>
            <origin xyz="0.0 0.0 0.0" rpy="0.0 0.0 0.0"/>
            <geometry>
                <cylinder radius="${caster_base_radius}" length="${caster_base_length}"/>
            </geometry>
        </visual>
        <collision>
            <origin xyz="0.0 0.0 0.0"/>
            <geometry>
                <cylinder radius="${caster_base_radius}" length="${caster_base_length}"/>
            </geometry>
        </collision>
    </link>

    <!-- Body to the caster base joint-->
    <joint name="body_casterbase_joint_${no}" type="continuous">
        <origin xyz="${caster_base_x} 0.0 ${caster_base_z}" rpy="0.0 0 0.0"/>
        <parent link="vehicle_body_${no}"/>
        <child link="caster_base_link_${no}"/>
        <axis xyz="0.0 0.0 1.0"/>
        <limit lower="0.0" upper="0.0" effort="0.0" velocity="0.0"/>
    </joint>

    <!-- Caster base to the caster wheel joint-->
    <joint name="casterbase_casterwheel_joint_${no}" type="continuous">
        <origin xyz="0.0 0.0 ${caster_wheel_z}" rpy="0.0 0.0 0.0"/>
        <parent link="caster_base_link_${no}"/>
        <child link="caster_wheel_link_${no}"/>
        <axis xyz="0.0 1.0 0.0"/>
        <limit lower="0.0" upper="0.0" effort="0.0" velocity="0.0"/>
    </joint>

    <!-- Gazebo control plugins-->
    <gazebo>
        <plugin name="gazebo_ros_control" filename= "libgazebo_ros_control.so">
         <robotNamespace>r4</robotNamespace>
        </plugin>
      </gazebo>
</robot>